matchTest.in
28800538 A b S 44.26 100
28800562 A c B 44.10 150
28800744 R b 100
28800758 A d B 44.18 120
28800773 A e S 44.38 100
28800812 A f B 44.18 157
28800974 A g S 44.27 100
28812071 R f 100
28813129 A h B 43.68 50
28813300 R f 57
28813830 A i S 44.18 100
28814087 A j S 44.18 1000
28814834 R c 100
28814864 A k B 44.50 100
28815804 A l B 44.80 175
28815937 R j 800
28816245 A m S 44.22 100
